<?xml version="1.0" encoding="utf-8"?>
<robot name="phantom_omni" xmlns:xacro="http://www.ros.org/wiki/xacro">
	
	<!-- Materials -->
	<material name="metal_seamed">
		<color rgba="0.4627450980392157 0.4666666666666667 0.4509803921568628 1.0" />
	</material>
	<material name="blue">
		<color rgba="0.0 0.0 0.8 1.0" />
	</material>
	<material name="white">
		<color rgba="1.0 1.0 1.0 1.0" />
    </material>
	
	<!-- Links -->
  <link name="base" >
    <visual>
			<origin xyz="0 -0.02 0" />
      <geometry>
				<mesh filename="package://omni_description/meshes/base.stl" />
      </geometry>
      <material name="metal_seamed"/>
    </visual>
  </link>
  <link name="torso" >
    <visual>
			<origin xyz="0 0 0.036" rpy="-1.5707 0 0"/>
      <geometry>
				<mesh filename="package://omni_description/meshes/torso.stl" />
      </geometry>
      <material name="blue"/>
    </visual>
  </link>
  <link name="upper_arm" >
		<visual>
			<origin xyz="0.0075 0 0" rpy="0 0 0"/>
      <geometry>
				<mesh filename="package://omni_description/meshes/upper_arm.stl" />
      </geometry>
      <material name="metal_seamed" />
    </visual>
  </link>
  <link name="lower_arm" >
		<visual>
			<origin xyz="0 0 0" rpy="1.5707 0 0"/>
      <geometry>
				<mesh filename="package://omni_description/meshes/lower_arm.stl" />
      </geometry>
      <material name="metal_seamed" />
    </visual>
  </link>
  <link name="wrist" >
		<visual>
			<origin xyz="0 0 0" rpy="3.14159 0 0"/>
      <geometry>
				<mesh filename="package://omni_description/meshes/wrist.stl" />
      </geometry>
      <material name="metal_seamed" />
    </visual>
  </link>
  <link name="tip" >
		<visual>
			<origin xyz="0 0 0" rpy="1.5707 0 0"/>
      <geometry>
				<mesh filename="package://omni_description/meshes/tip.stl" />
      </geometry>
      <material name="metal_seamed" />
    </visual>
  </link>
  <link name="stylus" >
    <visual>
			<origin xyz="0 0.013 0" rpy="1.5707 -1.5707 0"/>
      <geometry>
				<mesh filename="package://omni_description/meshes/pen.stl" />
      </geometry>
      <material name="blue" />
    </visual>
  </link>
  <link name="end_effector" >
  </link>
  
	<!-- joints -->
  <joint name="waist" type="revolute" >
    <parent link="base" />
    <child link="torso" />
    <origin xyz="0 0 0.09" rpy="0 0 0" />
    <axis xyz="0 0 1" />
    <limit lower="-0.98" upper="0.98" velocity="100" effort="5" />
  </joint>
  <joint name="shoulder" type="revolute" >
    <parent link="torso" />
    <child link="upper_arm" />
    <origin xyz="-0.0075 0 0.035" rpy="0.23 0 0" />
    <axis xyz="1 0 0" />
    <limit lower="-0.24" upper="1.57" velocity="100" effort="5" />
  </joint>
  <joint name="elbow" type="revolute" >
    <parent link="upper_arm" />
    <child link="lower_arm" />
    <origin xyz="0.0075 .134 0" rpy="-2.15 0 0" />
    <axis xyz="1 0 0" />
		<!-- upper="1.25" -->
    <limit lower="-0.2" upper="1.95" velocity="100" effort="5" /> 
  </joint>
  <joint name="wrist1" type="revolute" >
    <parent link="lower_arm" />
    <child link="wrist" />
    <origin xyz="0 0.08 0" rpy="0 0 0"  />
    <axis xyz="0 1 0" />
    <limit lower="-2.54" upper="2.60" velocity="100" effort="5" />
  </joint>
  <joint name="wrist2" type="revolute" >
    <parent link="wrist" />
    <child link="tip" />
    <origin xyz="0 0.0525 0" rpy="-0.85 0 0" />
    <axis xyz="1 0 0" />
    <limit lower="-2.07" upper="0.23" velocity="100" effort="5" />
  </joint>
  <joint name="wrist3" type="revolute" >
    <parent link="tip" />
    <child link="stylus" />
    <origin xyz="0 -0.023 0" rpy="0 0 0" />
    <axis xyz="0 1 0" />
    <limit lower="-2.34" upper="2.34" velocity="100" effort="5" />
  </joint>

  <joint name="effector_transform" type="fixed">
      <parent link="tip" />
      <child link="end_effector" />
      <origin xyz="0 0.031 0" rpy="0 0 0" />
  </joint>
</robot>

